<?xml version="1.0" encoding="UTF-8"?>
<testng-results retried="1" ignored="1" total="3" passed="0" failed="1" skipped="0">
  <reporter-output>
  </reporter-output>
  <suite started-at="2023-01-11T09:31:57 IST" name="Suite" finished-at="2023-01-11T09:32:08 IST" duration-ms="10530">
    <groups>
      <group name="Error Validation">
        <method signature="ErrorValidationsTest.LoginErrorValidation()[pri:0, instance:com.tests.ErrorValidationsTest@15aab8c6]" name="LoginErrorValidation" class="com.tests.ErrorValidationsTest"/>
      </group> <!-- Error Validation -->
    </groups>
    <test started-at="2023-01-11T09:31:57 IST" name="Error Validations Test" finished-at="2023-01-11T09:32:08 IST" duration-ms="10530">
      <class name="com.tests.ErrorValidationsTest">
        <test-method is-config="true" signature="launchApplication()[pri:0, instance:com.tests.ErrorValidationsTest@15aab8c6]" started-at="2023-01-11T09:31:57 IST" name="launchApplication" finished-at="2023-01-11T09:32:02 IST" duration-ms="4685" status="PASS">
          <reporter-output>
          </reporter-output>
        </test-method> <!-- launchApplication -->
        <test-method retried="true" signature="LoginErrorValidation()[pri:0, instance:com.tests.ErrorValidationsTest@15aab8c6]" started-at="2023-01-11T09:32:02 IST" name="LoginErrorValidation" finished-at="2023-01-11T09:32:02 IST" duration-ms="475" status="SKIP">
          <exception class="java.lang.AssertionError">
            <message>
              <![CDATA[expected [Incorrect email or password.] but found [Incorrect email or password]]]>
            </message>
            <full-stacktrace>
              <![CDATA[java.lang.AssertionError: expected [Incorrect email or password.] but found [Incorrect email or password]
at org.testng.Assert.fail(Assert.java:97)
at org.testng.Assert.assertEqualsImpl(Assert.java:136)
at org.testng.Assert.assertEquals(Assert.java:118)
at org.testng.Assert.assertEquals(Assert.java:575)
at org.testng.Assert.assertEquals(Assert.java:585)
at com.tests.ErrorValidationsTest.LoginErrorValidation(ErrorValidationsTest.java:24)
at java.base/jdk.internal.reflect.NativeMethodAccessorImpl.invoke0(Native Method)
at java.base/jdk.internal.reflect.NativeMethodAccessorImpl.invoke(NativeMethodAccessorImpl.java:77)
at java.base/jdk.internal.reflect.DelegatingMethodAccessorImpl.invoke(DelegatingMethodAccessorImpl.java:43)
at java.base/java.lang.reflect.Method.invoke(Method.java:568)
at org.testng.internal.MethodInvocationHelper.invokeMethod(MethodInvocationHelper.java:134)
at org.testng.internal.TestInvoker.invokeMethod(TestInvoker.java:597)
at org.testng.internal.TestInvoker.invokeTestMethod(TestInvoker.java:173)
at org.testng.internal.MethodRunner.runInSequence(MethodRunner.java:46)
at org.testng.internal.TestInvoker$MethodInvocationAgent.invoke(TestInvoker.java:816)
at org.testng.internal.TestInvoker.invokeTestMethods(TestInvoker.java:146)
at org.testng.internal.TestMethodWorker.invokeTestMethods(TestMethodWorker.java:146)
at org.testng.internal.TestMethodWorker.run(TestMethodWorker.java:128)
at java.base/java.util.ArrayList.forEach(ArrayList.java:1511)
at org.testng.TestRunner.privateRun(TestRunner.java:766)
at org.testng.TestRunner.run(TestRunner.java:587)
at org.testng.SuiteRunner.runTest(SuiteRunner.java:384)
at org.testng.SuiteRunner.access$000(SuiteRunner.java:28)
at org.testng.SuiteRunner$SuiteWorker.run(SuiteRunner.java:425)
at org.testng.internal.thread.ThreadUtil.lambda$execute$0(ThreadUtil.java:68)
at java.base/java.util.concurrent.FutureTask.run(FutureTask.java:264)
at java.base/java.util.concurrent.ThreadPoolExecutor.runWorker(ThreadPoolExecutor.java:1136)
at java.base/java.util.concurrent.ThreadPoolExecutor$Worker.run(ThreadPoolExecutor.java:635)
at java.base/java.lang.Thread.run(Thread.java:833)
]]>
            </full-stacktrace>
          </exception> <!-- java.lang.AssertionError -->
          <reporter-output>
          </reporter-output>
        </test-method> <!-- LoginErrorValidation -->
        <test-method is-config="true" signature="tearDown()[pri:0, instance:com.tests.ErrorValidationsTest@15aab8c6]" started-at="2023-01-11T09:32:02 IST" name="tearDown" finished-at="2023-01-11T09:32:02 IST" duration-ms="169" status="PASS">
          <reporter-output>
          </reporter-output>
        </test-method> <!-- tearDown -->
        <test-method is-config="true" signature="launchApplication()[pri:0, instance:com.tests.ErrorValidationsTest@15aab8c6]" started-at="2023-01-11T09:32:02 IST" name="launchApplication" finished-at="2023-01-11T09:32:06 IST" duration-ms="4049" status="PASS">
          <reporter-output>
          </reporter-output>
        </test-method> <!-- launchApplication -->
        <test-method signature="LoginErrorValidation()[pri:0, instance:com.tests.ErrorValidationsTest@15aab8c6]" started-at="2023-01-11T09:32:06 IST" name="LoginErrorValidation" finished-at="2023-01-11T09:32:07 IST" duration-ms="966" status="FAIL">
          <exception class="java.lang.AssertionError">
            <message>
              <![CDATA[expected [Incorrect email or password.] but found [Incorrect email or password]]]>
            </message>
            <full-stacktrace>
              <![CDATA[java.lang.AssertionError: expected [Incorrect email or password.] but found [Incorrect email or password]
at org.testng.Assert.fail(Assert.java:97)
at org.testng.Assert.assertEqualsImpl(Assert.java:136)
at org.testng.Assert.assertEquals(Assert.java:118)
at org.testng.Assert.assertEquals(Assert.java:575)
at org.testng.Assert.assertEquals(Assert.java:585)
at com.tests.ErrorValidationsTest.LoginErrorValidation(ErrorValidationsTest.java:24)
at java.base/jdk.internal.reflect.NativeMethodAccessorImpl.invoke0(Native Method)
at java.base/jdk.internal.reflect.NativeMethodAccessorImpl.invoke(NativeMethodAccessorImpl.java:77)
at java.base/jdk.internal.reflect.DelegatingMethodAccessorImpl.invoke(DelegatingMethodAccessorImpl.java:43)
at java.base/java.lang.reflect.Method.invoke(Method.java:568)
at org.testng.internal.MethodInvocationHelper.invokeMethod(MethodInvocationHelper.java:134)
at org.testng.internal.TestInvoker.invokeMethod(TestInvoker.java:597)
at org.testng.internal.TestInvoker.retryFailed(TestInvoker.java:213)
at org.testng.internal.MethodRunner.runInSequence(MethodRunner.java:58)
at org.testng.internal.TestInvoker$MethodInvocationAgent.invoke(TestInvoker.java:816)
at org.testng.internal.TestInvoker.invokeTestMethods(TestInvoker.java:146)
at org.testng.internal.TestMethodWorker.invokeTestMethods(TestMethodWorker.java:146)
at org.testng.internal.TestMethodWorker.run(TestMethodWorker.java:128)
at java.base/java.util.ArrayList.forEach(ArrayList.java:1511)
at org.testng.TestRunner.privateRun(TestRunner.java:766)
at org.testng.TestRunner.run(TestRunner.java:587)
at org.testng.SuiteRunner.runTest(SuiteRunner.java:384)
at org.testng.SuiteRunner.access$000(SuiteRunner.java:28)
at org.testng.SuiteRunner$SuiteWorker.run(SuiteRunner.java:425)
at org.testng.internal.thread.ThreadUtil.lambda$execute$0(ThreadUtil.java:68)
at java.base/java.util.concurrent.FutureTask.run(FutureTask.java:264)
at java.base/java.util.concurrent.ThreadPoolExecutor.runWorker(ThreadPoolExecutor.java:1136)
at java.base/java.util.concurrent.ThreadPoolExecutor$Worker.run(ThreadPoolExecutor.java:635)
at java.base/java.lang.Thread.run(Thread.java:833)
]]>
            </full-stacktrace>
          </exception> <!-- java.lang.AssertionError -->
          <reporter-output>
          </reporter-output>
        </test-method> <!-- LoginErrorValidation -->
        <test-method is-config="true" signature="tearDown()[pri:0, instance:com.tests.ErrorValidationsTest@15aab8c6]" started-at="2023-01-11T09:32:07 IST" name="tearDown" finished-at="2023-01-11T09:32:08 IST" duration-ms="143" status="PASS">
          <reporter-output>
          </reporter-output>
        </test-method> <!-- tearDown -->
      </class> <!-- com.tests.ErrorValidationsTest -->
    </test> <!-- Error Validations Test -->
  </suite> <!-- Suite -->
</testng-results>
